<?xml version="1.0" ?>
<robot name="panda_with_bat">

<material name="silver">
  <color rgba="0.700 0.700 0.700 1.000"/>
</material>

<link name="base_link">
  <inertial>
    <origin xyz="0.0 0.0 0.0" rpy="0 0 0"/>
    <mass value="0.0"/>
    <inertia ixx="0.0" iyy="0.0" izz="0.0" ixy="0.0" iyz="0.0" ixz="0.0"/>
  </inertial>
  <visual>
    <origin xyz="0 0 0" rpy="0 0 0"/>
    <geometry>
      <mesh filename="meshes/base_link.stl" scale="0.001 0.001 0.001"/>
    </geometry>
    <material name="silver"/>
    <material/>
  </visual>
  <collision>
    <origin xyz="0 0 0" rpy="0 0 0"/>
    <geometry>
      <mesh filename="meshes/base_link.stl" scale="0.001 0.001 0.001"/>
    </geometry>
  </collision>
</link>

<link name="franka_link11">
  <inertial>
    <origin xyz="0.015919970943145345 1.6891914177460943e-05 0.09629414483425225" rpy="0 0 0"/>
    <mass value="6.3428439995297925"/>
    <inertia ixx="0.049100885935681404" iyy="0.0523856265058229" izz="0.014510081328525493" ixy="-1.8118905784902939e-06" iyz="-1.2245628480900272e-05" ixz="-0.008761304137697046"/>
  </inertial>
  <visual>
    <origin xyz="0.205858 -0.115737 -0.489015" rpy="0 0 0"/>
    <geometry>
      <mesh filename="meshes/franka_link11.stl" scale="0.001 0.001 0.001"/>
    </geometry>
    <material name="silver"/>
    <material/>
  </visual>
  <collision>
    <origin xyz="0.205858 -0.115737 -0.489015" rpy="0 0 0"/>
    <geometry>
      <mesh filename="meshes/franka_link11.stl" scale="0.001 0.001 0.001"/>
    </geometry>
  </collision>
</link>

<link name="franka_link21">
  <inertial>
    <origin xyz="-0.03170674092862322 0.017918814413682704 0.06631353310618704" rpy="0 0 0"/>
    <mass value="18.093105171101435"/>
    <inertia ixx="0.1067043390002862" iyy="0.11527332715699679" izz="0.046421214515349085" ixy="-0.008156187945142945" iyz="-0.02011518479972141" ixz="-0.03011566655974729"/>
  </inertial>
  <visual>
    <origin xyz="0.205358 -0.115737 -0.681015" rpy="0 0 0"/>
    <geometry>
      <mesh filename="meshes/franka_link21.stl" scale="0.001 0.001 0.001"/>
    </geometry>
    <material name="silver"/>
    <material/>
  </visual>
  <collision>
    <origin xyz="0.205358 -0.115737 -0.681015" rpy="0 0 0"/>
    <geometry>
      <mesh filename="meshes/franka_link21.stl" scale="0.001 0.001 0.001"/>
    </geometry>
  </collision>
</link>

<link name="franka_link31">
  <inertial>
    <origin xyz="-0.006251688472462685 0.05415434031893715 0.055962521756316996" rpy="0 0 0"/>
    <mass value="5.091749656018345"/>
    <inertia ixx="0.027931566301489852" iyy="0.014324972489096588" izz="0.022896724524414103" ixy="0.0018985248869833327" iyz="-0.008999136283237785" ixz="0.0011251465327162258"/>
  </inertial>
  <visual>
    <origin xyz="0.204858 -0.166419 -0.868277" rpy="0 0 0"/>
    <geometry>
      <mesh filename="meshes/franka_link31.stl" scale="0.001 0.001 0.001"/>
    </geometry>
    <material name="silver"/>
    <material/>
  </visual>
  <collision>
    <origin xyz="0.204858 -0.166419 -0.868277" rpy="0 0 0"/>
    <geometry>
      <mesh filename="meshes/franka_link31.stl" scale="0.001 0.001 0.001"/>
    </geometry>
  </collision>
</link>

<link name="franka_link41">
  <inertial>
    <origin xyz="0.022416295539124442 0.053828750026371774 0.02831937415265595" rpy="0 0 0"/>
    <mass value="5.826518118660749"/>
    <inertia ixx="0.03293216879178651" iyy="0.013303916725328158" izz="0.029144926010459815" ixy="0.0018531124960448064" iyz="-0.008925637551683518" ixz="0.0008266307965244524"/>
  </inertial>
  <visual>
    <origin xyz="0.190744 -0.276493 -0.963839" rpy="0 0 0"/>
    <geometry>
      <mesh filename="meshes/franka_link41.stl" scale="0.001 0.001 0.001"/>
    </geometry>
    <material name="silver"/>
    <material/>
  </visual>
  <collision>
    <origin xyz="0.190744 -0.276493 -0.963839" rpy="0 0 0"/>
    <geometry>
      <mesh filename="meshes/franka_link41.stl" scale="0.001 0.001 0.001"/>
    </geometry>
  </collision>
</link>

<link name="franka_link51">
  <inertial>
    <origin xyz="-0.034290569507804514 0.16391278139547755 -0.04460213669811597" rpy="0 0 0"/>
    <mass value="2.33892655137443"/>
    <inertia ixx="0.02364118982761232" iyy="0.006151004442137342" izz="0.023577444571088457" ixy="0.002687874149010061" iyz="0.005125296561300452" ixz="-0.0007201380608680696"/>
  </inertial>
  <visual>
    <origin xyz="0.169284 -0.415935 -1.011568" rpy="0 0 0"/>
    <geometry>
      <mesh filename="meshes/franka_link51.stl" scale="0.001 0.001 0.001"/>
    </geometry>
    <material name="silver"/>
    <material/>
  </visual>
  <collision>
    <origin xyz="0.169284 -0.415935 -1.011568" rpy="0 0 0"/>
    <geometry>
      <mesh filename="meshes/franka_link51.stl" scale="0.001 0.001 0.001"/>
    </geometry>
  </collision>
</link>

<link name="franka_link61">
  <inertial>
    <origin xyz="0.03418688988700623 0.05926864819781541 -0.006268383799952537" rpy="0 0 0"/>
    <mass value="1.8155432010748516"/>
    <inertia ixx="0.007118089011445949" iyy="0.004265977942787158" izz="0.0051537386428838206" ixy="0.0004301101645506622" iyz="-0.00011646942799026228" ixz="-2.364473017452129e-05"/>
  </inertial>
  <visual>
    <origin xyz="0.138983 -0.664691 -0.944242" rpy="0 0 0"/>
    <geometry>
      <mesh filename="meshes/franka_link61.stl" scale="0.001 0.001 0.001"/>
    </geometry>
    <material name="silver"/>
    <material/>
  </visual>
  <collision>
    <origin xyz="0.138983 -0.664691 -0.944242" rpy="0 0 0"/>
    <geometry>
      <mesh filename="meshes/franka_link61.stl" scale="0.001 0.001 0.001"/>
    </geometry>
  </collision>
</link>

<link name="franka_link71">
  <inertial>
    <origin xyz="0.108837 -0.732388 -0.872878" rpy="0 0 0"/>
    <mass value="0.0"/>
    <inertia ixx="0.0" iyy="0.0" izz="0.0" ixy="0.0" iyz="0.0" ixz="0.0"/>
  </inertial>
  <visual>
    <origin xyz="0.108837 -0.732388 -0.872878" rpy="0 0 0"/>
    <geometry>
      <mesh filename="meshes/franka_link71.stl" scale="0.001 0.001 0.001"/>
    </geometry>
    <material name="silver"/>
    <material/>
  </visual>
  <collision>
    <origin xyz="0.108837 -0.732388 -0.872878" rpy="0 0 0"/>
    <geometry>
      <mesh filename="meshes/franka_link71.stl" scale="0.001 0.001 0.001"/>
    </geometry>
  </collision>
</link>

<link name="racquet1">
  <inertial>
    <origin xyz="1.8391212977947324e-06 -0.06077016046410544 -0.22453116041522347" rpy="0 0 0"/>
    <mass value="2.0593554197560686"/>
    <inertia ixx="0.05462064357594598" iyy="0.04736330697184776" izz="0.007660536139305729" ixy="-0.0007390303039475354" iyz="-0.011594971014470712" ixz="0.0002003713496647741"/>
  </inertial>
  <visual>
    <origin xyz="0.108837 -0.718333 -0.820946" rpy="0 0 0"/>
    <geometry>
      <mesh filename="meshes/racquet1.stl" scale="0.001 0.001 0.001"/>
    </geometry>
    <material name="silver"/>
    <material/>
  </visual>
  <collision>
    <origin xyz="0.108837 -0.718333 -0.820946" rpy="0 0 0"/>
    <geometry>
      <mesh filename="meshes/racquet1.stl" scale="0.001 0.001 0.001"/>
    </geometry>
  </collision>
</link>

<link name="end_effector1">
  <inertial>
    <origin xyz="0.0002457165873124695 -4.262776473851204e-05 1.1429791648920329e-05" rpy="0 0 0"/>
    <mass value="0.030826877913349836"/>
    <inertia ixx="3.792977295127495e-05" iyy="1.9830053182464703e-05" izz="1.930865310287473e-05" ixy="-3.24031739179758e-06" iyz="-1.5227106737666918e-07" ixz="8.769922430953286e-07"/>
  </inertial>
  <visual>
    <origin xyz="0.108345 -0.618421 -0.452131" rpy="0 0 0"/>
    <geometry>
      <mesh filename="meshes/end_effector1.stl" scale="0.001 0.001 0.001"/>
    </geometry>
    <material name="silver"/>
    <material/>
  </visual>
  <collision>
    <origin xyz="0.108345 -0.618421 -0.452131" rpy="0 0 0"/>
    <geometry>
      <mesh filename="meshes/end_effector1.stl" scale="0.001 0.001 0.001"/>
    </geometry>
  </collision>
</link>

<joint name="panda_joint0" type="continuous">
  <origin xyz="-0.205858 0.115737 0.489015" rpy="0 0 0"/>
  <parent link="base_link"/>
  <child link="franka_link11"/>
  <axis xyz="0.0 0.0 1.0"/>
</joint>
<transmission name="panda_joint0_tran">
  <type>transmission_interface/SimpleTransmission</type>
  <joint name="panda_joint0">
    <hardwareInterface>PositionJointInterface</hardwareInterface>
  </joint>
  <actuator name="panda_joint0_actr">
    <hardwareInterface>PositionJointInterface</hardwareInterface>
    <mechanicalReduction>1</mechanicalReduction>
  </actuator>
</transmission>

<joint name="panda_joint1" type="continuous">
  <origin xyz="0.0005 0.0 0.192" rpy="0 0 0"/>
  <parent link="franka_link11"/>
  <child link="franka_link21"/>
  <axis xyz="-1.0 0.0 0.0"/>
</joint>
<transmission name="panda_joint1_tran">
  <type>transmission_interface/SimpleTransmission</type>
  <joint name="panda_joint1">
    <hardwareInterface>PositionJointInterface</hardwareInterface>
  </joint>
  <actuator name="panda_joint1_actr">
    <hardwareInterface>PositionJointInterface</hardwareInterface>
    <mechanicalReduction>1</mechanicalReduction>
  </actuator>
</transmission>

<joint name="panda_joint2" type="continuous">
  <origin xyz="0.0005 0.050682 0.187262" rpy="0 0 0"/>
  <parent link="franka_link21"/>
  <child link="franka_link31"/>
  <axis xyz="0.0 0.261251 0.965271"/>
</joint>
<transmission name="panda_joint2_tran">
  <type>transmission_interface/SimpleTransmission</type>
  <joint name="panda_joint2">
    <hardwareInterface>PositionJointInterface</hardwareInterface>
  </joint>
  <actuator name="panda_joint2_actr">
    <hardwareInterface>PositionJointInterface</hardwareInterface>
    <mechanicalReduction>1</mechanicalReduction>
  </actuator>
</transmission>

<joint name="panda_joint3" type="continuous">
  <origin xyz="0.014114 0.110074 0.095562" rpy="0 0 0"/>
  <parent link="franka_link31"/>
  <child link="franka_link41"/>
  <axis xyz="0.984205 -0.170886 0.04625"/>
</joint>
<transmission name="panda_joint3_tran">
  <type>transmission_interface/SimpleTransmission</type>
  <joint name="panda_joint3">
    <hardwareInterface>PositionJointInterface</hardwareInterface>
  </joint>
  <actuator name="panda_joint3_actr">
    <hardwareInterface>PositionJointInterface</hardwareInterface>
    <mechanicalReduction>1</mechanicalReduction>
  </actuator>
</transmission>

<joint name="panda_joint4" type="continuous">
  <origin xyz="0.02146 0.139442 0.047729" rpy="0 0 0"/>
  <parent link="franka_link41"/>
  <child link="franka_link51"/>
  <axis xyz="0.177034 0.950024 -0.257124"/>
</joint>
<transmission name="panda_joint4_tran">
  <type>transmission_interface/SimpleTransmission</type>
  <joint name="panda_joint4">
    <hardwareInterface>PositionJointInterface</hardwareInterface>
  </joint>
  <actuator name="panda_joint4_actr">
    <hardwareInterface>PositionJointInterface</hardwareInterface>
    <mechanicalReduction>1</mechanicalReduction>
  </actuator>
</transmission>

<joint name="panda_joint5" type="continuous">
  <origin xyz="0.030301 0.248756 -0.067326" rpy="0 0 0"/>
  <parent link="franka_link51"/>
  <child link="franka_link61"/>
  <axis xyz="0.984205 -0.170886 0.04625"/>
</joint>
<transmission name="panda_joint5_tran">
  <type>transmission_interface/SimpleTransmission</type>
  <joint name="panda_joint5">
    <hardwareInterface>PositionJointInterface</hardwareInterface>
  </joint>
  <actuator name="panda_joint5_actr">
    <hardwareInterface>PositionJointInterface</hardwareInterface>
    <mechanicalReduction>1</mechanicalReduction>
  </actuator>
</transmission>

<joint name="panda_joint6" type="continuous">
  <origin xyz="0.030146 0.067697 -0.071364" rpy="0 0 0"/>
  <parent link="franka_link61"/>
  <child link="franka_link71"/>
  <axis xyz="-0.0 -0.261251 -0.965271"/>
</joint>
<transmission name="panda_joint6_tran">
  <type>transmission_interface/SimpleTransmission</type>
  <joint name="panda_joint6">
    <hardwareInterface>PositionJointInterface</hardwareInterface>
  </joint>
  <actuator name="panda_joint6_actr">
    <hardwareInterface>PositionJointInterface</hardwareInterface>
    <mechanicalReduction>1</mechanicalReduction>
  </actuator>
</transmission>

<joint name="panda_racquet_mount" type="fixed">
  <origin xyz="0.0 -0.014055 -0.051932" rpy="0 0 0"/>
  <parent link="franka_link71"/>
  <child link="racquet1"/>
</joint>

<joint name="Rigid_23" type="fixed">
  <origin xyz="0.000492 -0.099912 -0.368815" rpy="0 0 0"/>
  <parent link="racquet1"/>
  <child link="end_effector1"/>
</joint>

</robot>
