<?xml version="1.0" ?>
<robot name="panda_with_bat" xmlns:xacro="http://www.ros.org/wiki/xacro">

<xacro:include filename="$(find panda_with_bat_description)/urdf/materials.xacro" />
<xacro:include filename="$(find panda_with_bat_description)/urdf/panda_with_bat.trans" />
<xacro:include filename="$(find panda_with_bat_description)/urdf/panda_with_bat.gazebo" />
<link name="base_link">
  <inertial>
    <origin xyz="0.0 0.0 0.0" rpy="0 0 0"/>
    <mass value="0.0"/>
    <inertia ixx="0.0" iyy="0.0" izz="0.0" ixy="0.0" iyz="0.0" ixz="0.0"/>
  </inertial>
  <visual>
    <origin xyz="0 0 0" rpy="0 0 0"/>
    <geometry>
      <mesh filename="package://panda_with_bat_description/meshes/base_link.stl" scale="0.001 0.001 0.001"/>
    </geometry>
    <material name="silver"/>
  </visual>
  <collision>
    <origin xyz="0 0 0" rpy="0 0 0"/>
    <geometry>
      <mesh filename="package://panda_with_bat_description/meshes/base_link.stl" scale="0.001 0.001 0.001"/>
    </geometry>
  </collision>
</link>

<link name="franka_link1_1">
  <inertial>
    <origin xyz="0.015919970943145345 1.6891914177460943e-05 0.09629414483425225" rpy="0 0 0"/>
    <mass value="6.3428439995297925"/>
    <inertia ixx="0.049101" iyy="0.052386" izz="0.01451" ixy="-2e-06" iyz="-1.2e-05" ixz="-0.008761"/>
  </inertial>
  <visual>
    <origin xyz="0.205858 -0.115737 -0.489015" rpy="0 0 0"/>
    <geometry>
      <mesh filename="package://panda_with_bat_description/meshes/franka_link1_1.stl" scale="0.001 0.001 0.001"/>
    </geometry>
    <material name="silver"/>
  </visual>
  <collision>
    <origin xyz="0.205858 -0.115737 -0.489015" rpy="0 0 0"/>
    <geometry>
      <mesh filename="package://panda_with_bat_description/meshes/franka_link1_1.stl" scale="0.001 0.001 0.001"/>
    </geometry>
  </collision>
</link>

<link name="franka_link2_1">
  <inertial>
    <origin xyz="-0.03170674092862322 0.017918814413682704 0.06631353310618704" rpy="0 0 0"/>
    <mass value="18.093105171101435"/>
    <inertia ixx="0.106704" iyy="0.115273" izz="0.046421" ixy="-0.008156" iyz="-0.020115" ixz="-0.030116"/>
  </inertial>
  <visual>
    <origin xyz="0.205358 -0.115737 -0.681015" rpy="0 0 0"/>
    <geometry>
      <mesh filename="package://panda_with_bat_description/meshes/franka_link2_1.stl" scale="0.001 0.001 0.001"/>
    </geometry>
    <material name="silver"/>
  </visual>
  <collision>
    <origin xyz="0.205358 -0.115737 -0.681015" rpy="0 0 0"/>
    <geometry>
      <mesh filename="package://panda_with_bat_description/meshes/franka_link2_1.stl" scale="0.001 0.001 0.001"/>
    </geometry>
  </collision>
</link>

<link name="franka_link3_1">
  <inertial>
    <origin xyz="-0.006251688472462685 0.05415434031893715 0.055962521756316996" rpy="0 0 0"/>
    <mass value="5.091749656018345"/>
    <inertia ixx="0.027932" iyy="0.014325" izz="0.022897" ixy="0.001899" iyz="-0.008999" ixz="0.001125"/>
  </inertial>
  <visual>
    <origin xyz="0.204858 -0.166419 -0.868277" rpy="0 0 0"/>
    <geometry>
      <mesh filename="package://panda_with_bat_description/meshes/franka_link3_1.stl" scale="0.001 0.001 0.001"/>
    </geometry>
    <material name="silver"/>
  </visual>
  <collision>
    <origin xyz="0.204858 -0.166419 -0.868277" rpy="0 0 0"/>
    <geometry>
      <mesh filename="package://panda_with_bat_description/meshes/franka_link3_1.stl" scale="0.001 0.001 0.001"/>
    </geometry>
  </collision>
</link>

<link name="franka_link4_1">
  <inertial>
    <origin xyz="0.022416295539124442 0.053828750026371774 0.02831937415265595" rpy="0 0 0"/>
    <mass value="5.826518118660749"/>
    <inertia ixx="0.032932" iyy="0.013304" izz="0.029145" ixy="0.001853" iyz="-0.008926" ixz="0.000827"/>
  </inertial>
  <visual>
    <origin xyz="0.190744 -0.276493 -0.963839" rpy="0 0 0"/>
    <geometry>
      <mesh filename="package://panda_with_bat_description/meshes/franka_link4_1.stl" scale="0.001 0.001 0.001"/>
    </geometry>
    <material name="silver"/>
  </visual>
  <collision>
    <origin xyz="0.190744 -0.276493 -0.963839" rpy="0 0 0"/>
    <geometry>
      <mesh filename="package://panda_with_bat_description/meshes/franka_link4_1.stl" scale="0.001 0.001 0.001"/>
    </geometry>
  </collision>
</link>

<link name="franka_link5_1">
  <inertial>
    <origin xyz="-0.034290569507804514 0.16391278139547755 -0.04460213669811597" rpy="0 0 0"/>
    <mass value="2.33892655137443"/>
    <inertia ixx="0.023641" iyy="0.006151" izz="0.023577" ixy="0.002688" iyz="0.005125" ixz="-0.00072"/>
  </inertial>
  <visual>
    <origin xyz="0.169284 -0.415935 -1.011568" rpy="0 0 0"/>
    <geometry>
      <mesh filename="package://panda_with_bat_description/meshes/franka_link5_1.stl" scale="0.001 0.001 0.001"/>
    </geometry>
    <material name="silver"/>
  </visual>
  <collision>
    <origin xyz="0.169284 -0.415935 -1.011568" rpy="0 0 0"/>
    <geometry>
      <mesh filename="package://panda_with_bat_description/meshes/franka_link5_1.stl" scale="0.001 0.001 0.001"/>
    </geometry>
  </collision>
</link>

<link name="franka_link6_1">
  <inertial>
    <origin xyz="0.03418688988700623 0.05926864819781541 -0.006268383799952537" rpy="0 0 0"/>
    <mass value="1.8155432010748516"/>
    <inertia ixx="0.007118" iyy="0.004266" izz="0.005154" ixy="0.00043" iyz="-0.000116" ixz="-2.4e-05"/>
  </inertial>
  <visual>
    <origin xyz="0.138983 -0.664691 -0.944242" rpy="0 0 0"/>
    <geometry>
      <mesh filename="package://panda_with_bat_description/meshes/franka_link6_1.stl" scale="0.001 0.001 0.001"/>
    </geometry>
    <material name="silver"/>
  </visual>
  <collision>
    <origin xyz="0.138983 -0.664691 -0.944242" rpy="0 0 0"/>
    <geometry>
      <mesh filename="package://panda_with_bat_description/meshes/franka_link6_1.stl" scale="0.001 0.001 0.001"/>
    </geometry>
  </collision>
</link>

<link name="franka_link7_1">
  <inertial>
    <origin xyz="0.108837 -0.732388 -0.872878" rpy="0 0 0"/>
    <mass value="0.0"/>
    <inertia ixx="0.0" iyy="0.0" izz="0.0" ixy="0.0" iyz="0.0" ixz="0.0"/>
  </inertial>
  <visual>
    <origin xyz="0.108837 -0.732388 -0.872878" rpy="0 0 0"/>
    <geometry>
      <mesh filename="package://panda_with_bat_description/meshes/franka_link7_1.stl" scale="0.001 0.001 0.001"/>
    </geometry>
    <material name="silver"/>
  </visual>
  <collision>
    <origin xyz="0.108837 -0.732388 -0.872878" rpy="0 0 0"/>
    <geometry>
      <mesh filename="package://panda_with_bat_description/meshes/franka_link7_1.stl" scale="0.001 0.001 0.001"/>
    </geometry>
  </collision>
</link>

<link name="racquet_1">
  <inertial>
    <origin xyz="1.8391212977947324e-06 -0.06077016046410544 -0.22453116041522347" rpy="0 0 0"/>
    <mass value="2.0593554197560686"/>
    <inertia ixx="0.054621" iyy="0.047363" izz="0.007661" ixy="-0.000739" iyz="-0.011595" ixz="0.0002"/>
  </inertial>
  <visual>
    <origin xyz="0.108837 -0.718333 -0.820946" rpy="0 0 0"/>
    <geometry>
      <mesh filename="package://panda_with_bat_description/meshes/racquet_1.stl" scale="0.001 0.001 0.001"/>
    </geometry>
    <material name="silver"/>
  </visual>
  <collision>
    <origin xyz="0.108837 -0.718333 -0.820946" rpy="0 0 0"/>
    <geometry>
      <mesh filename="package://panda_with_bat_description/meshes/racquet_1.stl" scale="0.001 0.001 0.001"/>
    </geometry>
  </collision>
</link>

<link name="end_effector_1">
  <inertial>
    <origin xyz="0.0002457165873124695 -4.262776473851204e-05 1.1429791648920329e-05" rpy="0 0 0"/>
    <mass value="0.030826877913349836"/>
    <inertia ixx="3.8e-05" iyy="2e-05" izz="1.9e-05" ixy="-3e-06" iyz="-0.0" ixz="1e-06"/>
  </inertial>
  <visual>
    <origin xyz="0.108345 -0.618421 -0.452131" rpy="0 0 0"/>
    <geometry>
      <mesh filename="package://panda_with_bat_description/meshes/end_effector_1.stl" scale="0.001 0.001 0.001"/>
    </geometry>
    <material name="silver"/>
  </visual>
  <collision>
    <origin xyz="0.108345 -0.618421 -0.452131" rpy="0 0 0"/>
    <geometry>
      <mesh filename="package://panda_with_bat_description/meshes/end_effector_1.stl" scale="0.001 0.001 0.001"/>
    </geometry>
  </collision>
</link>

<joint name="panda_joint0" type="continuous">
  <origin xyz="-0.205858 0.115737 0.489015" rpy="0 0 0"/>
  <parent link="base_link"/>
  <child link="franka_link1_1"/>
  <axis xyz="0.0 0.0 1.0"/>
</joint>

<joint name="panda_joint1" type="continuous">
  <origin xyz="0.0005 0.0 0.192" rpy="0 0 0"/>
  <parent link="franka_link1_1"/>
  <child link="franka_link2_1"/>
  <axis xyz="-1.0 0.0 0.0"/>
</joint>

<joint name="panda_joint2" type="continuous">
  <origin xyz="0.0005 0.050682 0.187262" rpy="0 0 0"/>
  <parent link="franka_link2_1"/>
  <child link="franka_link3_1"/>
  <axis xyz="0.0 0.261251 0.965271"/>
</joint>

<joint name="panda_joint3" type="continuous">
  <origin xyz="0.014114 0.110074 0.095562" rpy="0 0 0"/>
  <parent link="franka_link3_1"/>
  <child link="franka_link4_1"/>
  <axis xyz="0.984205 -0.170886 0.04625"/>
</joint>

<joint name="panda_joint4" type="continuous">
  <origin xyz="0.02146 0.139442 0.047729" rpy="0 0 0"/>
  <parent link="franka_link4_1"/>
  <child link="franka_link5_1"/>
  <axis xyz="0.177034 0.950024 -0.257124"/>
</joint>

<joint name="panda_joint5" type="continuous">
  <origin xyz="0.030301 0.248756 -0.067326" rpy="0 0 0"/>
  <parent link="franka_link5_1"/>
  <child link="franka_link6_1"/>
  <axis xyz="0.984205 -0.170886 0.04625"/>
</joint>

<joint name="panda_joint6" type="continuous">
  <origin xyz="0.030146 0.067697 -0.071364" rpy="0 0 0"/>
  <parent link="franka_link6_1"/>
  <child link="franka_link7_1"/>
  <axis xyz="-0.0 -0.261251 -0.965271"/>
</joint>

<joint name="panda_racquet_mount" type="fixed">
  <origin xyz="0.0 -0.014055 -0.051932" rpy="0 0 0"/>
  <parent link="franka_link7_1"/>
  <child link="racquet_1"/>
</joint>

<joint name="Rigid 23" type="fixed">
  <origin xyz="0.000492 -0.099912 -0.368815" rpy="0 0 0"/>
  <parent link="racquet_1"/>
  <child link="end_effector_1"/>
</joint>

</robot>
